try:
    print(x)
except:
    print("Something went wrong..!!")
finally:
    print("The 'Try-except' is finished")
